{'message_id': 403, 'from': {'id': 416552809, 'is_bot': False, 'first_name': 'Beknur', 'last_name': 'Kattabekov', 'username': 'Beknur_K', 'language_code': 'en-US'}, 'chat': {'id': 416552809, 'first_name': 'Beknur', 'last_name': 'Kattabekov', 'username': 'Beknur_K', 'type': 'private'}, 'date': 1532949035, 'text': '/start', 'entities': [{'offset': 0, 'length': 6, 'type': 'bot_command'}]}
{'message_id': 405, 'from': {'id': 416552809, 'is_bot': False, 'first_name': 'Beknur', 'last_name': 'Kattabekov', 'username': 'Beknur_K', 'language_code': 'en-US'}, 'chat': {'id': 416552809, 'first_name': 'Beknur', 'last_name': 'Kattabekov', 'username': 'Beknur_K', 'type': 'private'}, 'date': 1532949195, 'text': '/tweet', 'entities': [{'offset': 0, 'length': 6, 'type': 'bot_command'}]}
{'message_id': 407, 'from': {'id': 416552809, 'is_bot': False, 'first_name': 'Beknur', 'last_name': 'Kattabekov', 'username': 'Beknur_K', 'language_code': 'en-US'}, 'chat': {'id': 416552809, 'first_name': 'Beknur', 'last_name': 'Kattabekov', 'username': 'Beknur_K', 'type': 'private'}, 'date': 1532949219, 'text': 'OO OOOOO bullish'}
OO OOOOO bullish
Traceback (most recent call last):
  File "/home/beknur/anaconda3/lib/python3.6/site-packages/pandas/core/indexes/base.py", line 2442, in get_loc
    return self._engine.get_loc(key)
  File "pandas/_libs/index.pyx", line 132, in pandas._libs.index.IndexEngine.get_loc
  File "pandas/_libs/index.pyx", line 154, in pandas._libs.index.IndexEngine.get_loc
  File "pandas/_libs/hashtable_class_helper.pxi", line 1210, in pandas._libs.hashtable.PyObjectHashTable.get_item
  File "pandas/_libs/hashtable_class_helper.pxi", line 1218, in pandas._libs.hashtable.PyObjectHashTable.get_item
KeyError: 'text'

During handling of the above exception, another exception occurred:

Traceback (most recent call last):
  File "multiple_tweets.py", line 197, in <module>
    obj.main()
  File "multiple_tweets.py", line 191, in main
    self.handle_updates(updates)
  File "multiple_tweets.py", line 118, in handle_updates
    if temp_list[2] in df['text'][n]:
  File "/home/beknur/anaconda3/lib/python3.6/site-packages/pandas/core/frame.py", line 1964, in __getitem__
    return self._getitem_column(key)
  File "/home/beknur/anaconda3/lib/python3.6/site-packages/pandas/core/frame.py", line 1971, in _getitem_column
    return self._get_item_cache(key)
  File "/home/beknur/anaconda3/lib/python3.6/site-packages/pandas/core/generic.py", line 1645, in _get_item_cache
    values = self._data.get(item)
  File "/home/beknur/anaconda3/lib/python3.6/site-packages/pandas/core/internals.py", line 3590, in get
    loc = self.items.get_loc(item)
  File "/home/beknur/anaconda3/lib/python3.6/site-packages/pandas/core/indexes/base.py", line 2444, in get_loc
    return self._engine.get_loc(self._maybe_cast_indexer(key))
  File "pandas/_libs/index.pyx", line 132, in pandas._libs.index.IndexEngine.get_loc
  File "pandas/_libs/index.pyx", line 154, in pandas._libs.index.IndexEngine.get_loc
  File "pandas/_libs/hashtable_class_helper.pxi", line 1210, in pandas._libs.hashtable.PyObjectHashTable.get_item
  File "pandas/_libs/hashtable_class_helper.pxi", line 1218, in pandas._libs.hashtable.PyObjectHashTable.get_item
KeyError: 'text'
{'message_id': 419, 'from': {'id': 416552809, 'is_bot': False, 'first_name': 'Beknur', 'last_name': 'Kattabekov', 'username': 'Beknur_K', 'language_code': 'en-US'}, 'chat': {'id': 416552809, 'first_name': 'Beknur', 'last_name': 'Kattabekov', 'username': 'Beknur_K', 'type': 'private'}, 'date': 1532951271, 'text': '/tweet', 'entities': [{'offset': 0, 'length': 6, 'type': 'bot_command'}]}
{'message_id': 422, 'from': {'id': 416552809, 'is_bot': False, 'first_name': 'Beknur', 'last_name': 'Kattabekov', 'username': 'Beknur_K', 'language_code': 'en-US'}, 'chat': {'id': 416552809, 'first_name': 'Beknur', 'last_name': 'Kattabekov', 'username': 'Beknur_K', 'type': 'private'}, 'date': 1532951294, 'text': '/tweet', 'entities': [{'offset': 0, 'length': 6, 'type': 'bot_command'}]}
{'message_id': 425, 'from': {'id': 416552809, 'is_bot': False, 'first_name': 'Beknur', 'last_name': 'Kattabekov', 'username': 'Beknur_K', 'language_code': 'en-US'}, 'chat': {'id': 416552809, 'first_name': 'Beknur', 'last_name': 'Kattabekov', 'username': 'Beknur_K', 'type': 'private'}, 'date': 1532951304, 'text': '/start', 'entities': [{'offset': 0, 'length': 6, 'type': 'bot_command'}]}
{'message_id': 428, 'from': {'id': 416552809, 'is_bot': False, 'first_name': 'Beknur', 'last_name': 'Kattabekov', 'username': 'Beknur_K', 'language_code': 'en-US'}, 'chat': {'id': 416552809, 'first_name': 'Beknur', 'last_name': 'Kattabekov', 'username': 'Beknur_K', 'type': 'private'}, 'date': 1532951328, 'text': '/start', 'entities': [{'offset': 0, 'length': 6, 'type': 'bot_command'}]}
{'message_id': 430, 'from': {'id': 416552809, 'is_bot': False, 'first_name': 'Beknur', 'last_name': 'Kattabekov', 'username': 'Beknur_K', 'language_code': 'en-US'}, 'chat': {'id': 416552809, 'first_name': 'Beknur', 'last_name': 'Kattabekov', 'username': 'Beknur_K', 'type': 'private'}, 'date': 1532951334, 'text': '/tweet', 'entities': [{'offset': 0, 'length': 6, 'type': 'bot_command'}]}
{'message_id': 432, 'from': {'id': 416552809, 'is_bot': False, 'first_name': 'Beknur', 'last_name': 'Kattabekov', 'username': 'Beknur_K', 'language_code': 'en-US'}, 'chat': {'id': 416552809, 'first_name': 'Beknur', 'last_name': 'Kattabekov', 'username': 'Beknur_K', 'type': 'private'}, 'date': 1532951385, 'text': 'AHE Google bullish'}
AHE Google bullish
{'message_id': 434, 'from': {'id': 416552809, 'is_bot': False, 'first_name': 'Beknur', 'last_name': 'Kattabekov', 'username': 'Beknur_K', 'language_code': 'en-US'}, 'chat': {'id': 416552809, 'first_name': 'Beknur', 'last_name': 'Kattabekov', 'username': 'Beknur_K', 'type': 'private'}, 'date': 1532951394, 'document': {'file_name': 'image.png', 'mime_type': 'image/png', 'file_id': 'BQADAgADCgIAAqmb-EqXxmdd3xwgrAI', 'file_size': 3212}}
BQADAgADCgIAAqmb-EqXxmdd3xwgrAI
https://api.telegram.org/file/bot686702879:AAFS1SlBKg3BVozmdgnVrmctK0-cwkBgykI/documents/file_23.png

{'message_id': 436, 'from': {'id': 416552809, 'is_bot': False, 'first_name': 'Beknur', 'last_name': 'Kattabekov', 'username': 'Beknur_K', 'language_code': 'en-US'}, 'chat': {'id': 416552809, 'first_name': 'Beknur', 'last_name': 'Kattabekov', 'username': 'Beknur_K', 'type': 'private'}, 'date': 1532951439, 'text': '/tweet', 'entities': [{'offset': 0, 'length': 6, 'type': 'bot_command'}]}
{'message_id': 438, 'from': {'id': 416552809, 'is_bot': False, 'first_name': 'Beknur', 'last_name': 'Kattabekov', 'username': 'Beknur_K', 'language_code': 'en-US'}, 'chat': {'id': 416552809, 'first_name': 'Beknur', 'last_name': 'Kattabekov', 'username': 'Beknur_K', 'type': 'private'}, 'date': 1532951456, 'text': 'PPH Google bullish'}
PPH Google bullish
{'message_id': 440, 'from': {'id': 416552809, 'is_bot': False, 'first_name': 'Beknur', 'last_name': 'Kattabekov', 'username': 'Beknur_K', 'language_code': 'en-US'}, 'chat': {'id': 416552809, 'first_name': 'Beknur', 'last_name': 'Kattabekov', 'username': 'Beknur_K', 'type': 'private'}, 'date': 1532951467, 'document': {'file_name': 'file_20.jpg', 'mime_type': 'image/jpeg', 'thumb': {'file_id': 'AAQCABNOPLYOAASyva7dw7w2sKyPAAIC', 'file_size': 1802, 'width': 90, 'height': 51}, 'file_id': 'BQADAgADCwIAAqmb-EpZJYZIho46hgI', 'file_size': 533041}}
BQADAgADCwIAAqmb-EpZJYZIho46hgI
https://api.telegram.org/file/bot686702879:AAFS1SlBKg3BVozmdgnVrmctK0-cwkBgykI/documents/file_24.jpg

{'message_id': 442, 'from': {'id': 416552809, 'is_bot': False, 'first_name': 'Beknur', 'last_name': 'Kattabekov', 'username': 'Beknur_K', 'language_code': 'en-US'}, 'chat': {'id': 416552809, 'first_name': 'Beknur', 'last_name': 'Kattabekov', 'username': 'Beknur_K', 'type': 'private'}, 'date': 1532951538, 'text': '/tweet', 'entities': [{'offset': 0, 'length': 6, 'type': 'bot_command'}]}
{'message_id': 444, 'from': {'id': 416552809, 'is_bot': False, 'first_name': 'Beknur', 'last_name': 'Kattabekov', 'username': 'Beknur_K', 'language_code': 'en-US'}, 'chat': {'id': 416552809, 'first_name': 'Beknur', 'last_name': 'Kattabekov', 'username': 'Beknur_K', 'type': 'private'}, 'date': 1532951554, 'text': 'AAA AAAAA bullish'}
AAA AAAAA bullish
{'message_id': 446, 'from': {'id': 416552809, 'is_bot': False, 'first_name': 'Beknur', 'last_name': 'Kattabekov', 'username': 'Beknur_K', 'language_code': 'en-US'}, 'chat': {'id': 416552809, 'first_name': 'Beknur', 'last_name': 'Kattabekov', 'username': 'Beknur_K', 'type': 'private'}, 'date': 1532951560, 'document': {'file_name': 'file_1.png', 'mime_type': 'image/png', 'file_id': 'BQADAgADDAIAAqmb-EpTBdIk9qFOOwI', 'file_size': 3212}}
BQADAgADDAIAAqmb-EpTBdIk9qFOOwI
https://api.telegram.org/file/bot686702879:AAFS1SlBKg3BVozmdgnVrmctK0-cwkBgykI/documents/file_25.png

{'message_id': 448, 'from': {'id': 416552809, 'is_bot': False, 'first_name': 'Beknur', 'last_name': 'Kattabekov', 'username': 'Beknur_K', 'language_code': 'en-US'}, 'chat': {'id': 416552809, 'first_name': 'Beknur', 'last_name': 'Kattabekov', 'username': 'Beknur_K', 'type': 'private'}, 'date': 1532952056, 'text': '/start', 'entities': [{'offset': 0, 'length': 6, 'type': 'bot_command'}]}
Traceback (most recent call last):
  File "/home/beknur/anaconda3/lib/python3.6/site-packages/urllib3/connection.py", line 141, in _new_conn
    (self.host, self.port), self.timeout, **extra_kw)
  File "/home/beknur/anaconda3/lib/python3.6/site-packages/urllib3/util/connection.py", line 83, in create_connection
    raise err
  File "/home/beknur/anaconda3/lib/python3.6/site-packages/urllib3/util/connection.py", line 73, in create_connection
    sock.connect(sa)
OSError: [Errno 101] Network is unreachable

During handling of the above exception, another exception occurred:

Traceback (most recent call last):
  File "/home/beknur/anaconda3/lib/python3.6/site-packages/urllib3/connectionpool.py", line 601, in urlopen
    chunked=chunked)
  File "/home/beknur/anaconda3/lib/python3.6/site-packages/urllib3/connectionpool.py", line 346, in _make_request
    self._validate_conn(conn)
  File "/home/beknur/anaconda3/lib/python3.6/site-packages/urllib3/connectionpool.py", line 850, in _validate_conn
    conn.connect()
  File "/home/beknur/anaconda3/lib/python3.6/site-packages/urllib3/connection.py", line 284, in connect
    conn = self._new_conn()
  File "/home/beknur/anaconda3/lib/python3.6/site-packages/urllib3/connection.py", line 150, in _new_conn
    self, "Failed to establish a new connection: %s" % e)
urllib3.exceptions.NewConnectionError: <urllib3.connection.VerifiedHTTPSConnection object at 0x7f80735f7390>: Failed to establish a new connection: [Errno 101] Network is unreachable

During handling of the above exception, another exception occurred:

Traceback (most recent call last):
  File "/home/beknur/anaconda3/lib/python3.6/site-packages/requests/adapters.py", line 440, in send
    timeout=timeout
  File "/home/beknur/anaconda3/lib/python3.6/site-packages/urllib3/connectionpool.py", line 639, in urlopen
    _stacktrace=sys.exc_info()[2])
  File "/home/beknur/anaconda3/lib/python3.6/site-packages/urllib3/util/retry.py", line 388, in increment
    raise MaxRetryError(_pool, url, error or ResponseError(cause))
urllib3.exceptions.MaxRetryError: HTTPSConnectionPool(host='api.telegram.org', port=443): Max retries exceeded with url: /bot686702879:AAFS1SlBKg3BVozmdgnVrmctK0-cwkBgykI/getUpdates?timeout=100&offset=787056022 (Caused by NewConnectionError('<urllib3.connection.VerifiedHTTPSConnection object at 0x7f80735f7390>: Failed to establish a new connection: [Errno 101] Network is unreachable',))

During handling of the above exception, another exception occurred:

Traceback (most recent call last):
  File "multiple_tweets.py", line 197, in <module>
    obj.main()
  File "multiple_tweets.py", line 187, in main
    updates = self.get_updates(last_update_id)
  File "multiple_tweets.py", line 35, in get_updates
    js = self.get_json_from_url(url)
  File "multiple_tweets.py", line 27, in get_json_from_url
    content = self.get_url(url)
  File "multiple_tweets.py", line 22, in get_url
    response = requests.get(url)
  File "/home/beknur/anaconda3/lib/python3.6/site-packages/requests/api.py", line 72, in get
    return request('get', url, params=params, **kwargs)
  File "/home/beknur/anaconda3/lib/python3.6/site-packages/requests/api.py", line 58, in request
    return session.request(method=method, url=url, **kwargs)
  File "/home/beknur/anaconda3/lib/python3.6/site-packages/requests/sessions.py", line 508, in request
    resp = self.send(prep, **send_kwargs)
  File "/home/beknur/anaconda3/lib/python3.6/site-packages/requests/sessions.py", line 618, in send
    r = adapter.send(request, **kwargs)
  File "/home/beknur/anaconda3/lib/python3.6/site-packages/requests/adapters.py", line 508, in send
    raise ConnectionError(e, request=request)
requests.exceptions.ConnectionError: HTTPSConnectionPool(host='api.telegram.org', port=443): Max retries exceeded with url: /bot686702879:AAFS1SlBKg3BVozmdgnVrmctK0-cwkBgykI/getUpdates?timeout=100&offset=787056022 (Caused by NewConnectionError('<urllib3.connection.VerifiedHTTPSConnection object at 0x7f80735f7390>: Failed to establish a new connection: [Errno 101] Network is unreachable',))
